# Сбор и разметка данных

## Семинар 6

Была проблема с отладкой: при обычном запуске всё шло хорошо (см. run.log), а при отладке возникала ошибка (см. debag.log).

Как оказалось, это из-за включенного по умолчанию Asyncio support for the debugger в PyCharm (стоял 2024.1)

**Решение**
1. Нажмите Shift + Shift => Search Everywhere (Искать везде).
2. Во всплывающем окне введите: "Registry" и нажмите Enter.
3. Найдите "Registry" в списке результатов и кликните на нём.
4. В новом всплывающем окне найдите python.debug.asyncio.replстроку и снимите его флажок.
5. Кликните "Close".
6. Перезапустите IDE (у меня применилось без перезагрузки).
